Workbook
Name Slicer_Product_Category: #N/A
Name Slicer_Marketing_Channel: #N/A
Name Slicer_Payment_Method: #N/A
Name Slicer_Years__Order_Date: #N/A

Sheet PIVOT TABLE
A3: Product Category | B3: Sum of Total order | G3: Buyer Region | H3: Sum of Total order | K3: Years (Order Date) | L3: Order Date | M3: Sum of Total order
A4: Apparel | B4: 222903.91 | G4: Asia-Pacific | H4: 375802.64 | K4: 2022
A5: Beauty | B5: 66615.504 | G5: Europe | H5: 727944.64 | L5: Jan | M5: 59836.788
A6: Ceramics | B6: 229865.67 | G6: Latin America | H6: 157588.07 | L6: Feb | M6: 52722.3
A7: Home Decor | B7: 630094.11 | G7: Middle East & Africa | H7: 98987.405 | L7: Mar | M7: 60630.178
A8: Jewelry | B8: 542320.59 | G8: North America | H8: 1189343.6 | L8: Apr | M8: 53450.421
A9: Paper Goods | B9: 69024.783 | G9: Grand Total | H9: 2549666.3 | L9: May | M9: 67182.519
A10: Textiles | B10: 181618.36 | L10: Jun | M10: 59236.675
A11: Woodwork | B11: 607223.4 | L11: Jul | M11: 56531.192
A12: Grand Total | B12: 2549666.3 | G12: Payment Method | H12: Percentage | L12: Aug | M12: 62993.174
G13: Apple Pay | H13: 0.1212239 | L13: Sep | M13: 48448.296
G14: Bank Transfer | H14: 0.048354151 | L14: Oct | M14: 65082.796
A15: Product Category | B15: Sum of Discout Amount | G15: Credit Card | H15: 0.44788506 | L15: Nov | M15: 53511.966
A16: Paper Goods | B16: 1068.1571 | G16: Google Pay | H16: 0.10585812 | L16: Dec | M16: 59512.873
A17: Beauty | B17: 1109.3259 | G17: PayPal | H17: 0.27667877 | K17: 2023
A18: Textiles | B18: 3847.5454 | G18: Grand Total | H18: 1 | L18: Jan | M18: 51737.932
A19: Apparel | B19: 3910.2233 | L19: Feb | M19: 53152.161
A20: Ceramics | B20: 4322.1615 | G20: Marketing Channel | H20: Sum of Total order | L20: Mar | M20: 54594.027
A21: Jewelry | B21: 10703.937 | G21: Direct | H21: 238302.26 | L21: Apr | M21: 56087.841
A22: Woodwork | B22: 12009.69 | G22: Email | H22: 252058.53 | L22: May | M22: 61217.274
A23: Home Decor | B23: 13131.38 | G23: Organic Search | H23: 809963.69 | L23: Jun | M23: 56869.334
A24: Grand Total | B24: 50102.421 | G24: Paid Ads | H24: 470163.45 | L24: Jul | M24: 51161.356
G25: Referral | H25: 157231 | L25: Aug | M25: 67395.652
A26: Is Custom Order | B26: Sum of Total order | C26: Percentage | G26: Social Media | H26: 621947.39 | L26: Sep | M26: 63448.849
A27: FALSE | B27: 2076889.7 | C27: 0.81457313 | G27: Grand Total | H27: 2549666.3 | L27: Oct | M27: 60358.226
A28: TRUE | B28: 472776.65 | C28: 0.18542687 | L28: Nov | M28: 56991.181
A29: Grand Total | B29: 2549666.3 | C29: 1 | L29: Dec | M29: 51408.109
G30: Product Category | H30: Sum of Shipping Cost | K30: 2024
A31: Product Category | B31: Sum of Quantity | C31: Sum of Total order | D31: Average of Total order | E31: Average of Customer Rating | G31: Apparel | H31: 27169.96 | L31: Jan | M31: 58912.104
A32: Apparel | B32: 2736 | C32: 222903.91 | D32: 129.82173 | E32: 4.3587653 | G32: Beauty | H32: 15899.57 | L32: Feb | M32: 64097.371
A33: Beauty | B33: 1607 | C33: 66615.504 | D33: 63.082864 | E33: 4.3210227 | G33: Ceramics | H33: 34683.82 | L33: Mar | M33: 56587.821
A34: Ceramics | B34: 3579 | C34: 229865.67 | D34: 102.84817 | E34: 4.3402685 | G34: Home Decor | H34: 47462.32 | L34: Apr | M34: 58712.25
A35: Home Decor | B35: 4473 | C35: 630094.11 | D35: 225.35555 | E35: 4.3555079 | G35: Jewelry | H35: 53086.11 | L35: May | M35: 53169.197
A36: Jewelry | B36: 5211 | C36: 542320.59 | D36: 166.56038 | E36: 4.3507371 | G36: Paper Goods | H36: 18127.13 | L36: Jun | M36: 54704.572
A37: Paper Goods | B37: 2011 | C37: 69024.783 | D37: 55.935805 | E37: 4.3464344 | G37: Textiles | H37: 18526.97 | L37: Jul | M37: 61722.223
A38: Textiles | B38: 1801 | C38: 181618.36 | D38: 156.4327 | E38: 4.3514212 | G38: Woodwork | H38: 29101.79 | L38: Aug | M38: 57167.9
A39: Woodwork | B39: 2478 | C39: 607223.4 | D39: 393.02485 | E39: 4.3822006 | G39: Grand Total | H39: 244057.67 | L39: Sep | M39: 51087.901
A40: Grand Total | B40: 23896 | C40: 2549666.3 | D40: 169.97776 | E40: 4.3518333 | L40: Oct | M40: 53700.054
L41: Nov | M41: 50097.496
L42: Dec | M42: 47895.519
...

Sheet CLEANED DATA
A1: Transaction ID | B1: Order Date | C1: Seller ID | D1: Product Category | E1: Product Subcategory | F1: Unit Price | G1: Quantity | H1: Discount % | I1: Discout Amount | J1: Gross Revenue | K1: Net Revenue | L1: Shipping Cost | M1: Total order | N1: Buyer Region | O1: Delivery Days | P1: Customer Rating | Q1: Is Custom Order | R1: Seller Experience Years | S1: Marketing Channel | T1: Payment Method | V1: Grand Total Order
A2: TXN-011235 | B2: 44562 | C2: SELL-7083 | D2: Woodwork | E2: Furniture | F2: 194.1 | G2: 4 | H2: 0 | I2: =H2*F2/100 -> 0 | J2: =G2*F2 -> 776.4 | K2: =J2-I2 -> 776.4 | L2: 16.51 | M2: =K2+L2 -> 792.91 | N2: North America | O2: 5 | P2: 4.5 | Q2: FALSE | R2: 4 | S2: Social Media | T2: Google Pay | V2: =SUM(M:M) -> 2549666.3
A3: TXN-003905 | B3: 44562 | C3: SELL-1776 | D3: Beauty | E3: Bath Bombs | F3: 19.93 | G3: 1 | H3: 0 | I3: =H3*F3/100 -> 0 | J3: =G3*F3 -> 19.93 | K3: =J3-I3 -> 19.93 | L3: 17.27 | M3: =K3+L3 -> 37.2 | N3: Latin America | O3: 20 | P3: 5 | Q3: FALSE | R3: 9 | S3: Referral | T3: Credit Card
A4: TXN-007755 | B4: 44562 | C4: SELL-2195 | D4: Jewelry | E4: Rings | F4: 90.61 | G4: 3 | H4: 0 | I4: =H4*F4/100 -> 0 | J4: =G4*F4 -> 271.83 | K4: =J4-I4 -> 271.83 | L4: 16.59 | M4: =K4+L4 -> 288.42 | N4: Europe | O4: 5 | P4: 3 | Q4: FALSE | R4: 12 | S4: Paid Ads | T4: Google Pay | V4: Average Revenue
A5: TXN-009298 | B5: 44562 | C5: SELL-7278 | D5: Home Decor | E5: Wall Art | F5: 232.56 | G5: 1 | H5: 0 | I5: =H5*F5/100 -> 0 | J5: =G5*F5 -> 232.56 | K5: =J5-I5 -> 232.56 | L5: 24.87 | M5: =K5+L5 -> 257.43 | N5: Latin America | O5: 8 | P5: 3.5 | Q5: FALSE | R5: 3 | S5: Social Media | T5: Apple Pay | V5: =AVERAGE(M:M) -> 169.97776
A6: TXN-000748 | B6: 44562 | C6: SELL-6750 | D6: Jewelry | E6: Rings | F6: 143.93 | G6: 2 | H6: 0 | I6: =H6*F6/100 -> 0 | J6: =G6*F6 -> 287.86 | K6: =J6-I6 -> 287.86 | L6: 16.71 | M6: =K6+L6 -> 304.57 | N6: Europe | O6: 6 | P6: 2.5 | Q6: TRUE | R6: 8 | S6: Paid Ads | T6: Credit Card
A7: TXN-003699 | B7: 44562 | C7: SELL-4940 | D7: Woodwork | E7: Toys | F7: 163.91 | G7: 1 | H7: 15 | I7: =H7*F7/100 -> 24.5865 | J7: =G7*F7 -> 163.91 | K7: =J7-I7 -> 139.3235 | L7: 13.25 | M7: =K7+L7 -> 152.5735 | N7: North America | O7: 5 | P7: 5 | Q7: FALSE | R7: 4 | S7: Organic Search | T7: Credit Card | V7: Total quantiy
A8: TXN-012824 | B8: 44562 | C8: SELL-5304 | D8: Ceramics | E8: Plates | F8: 79.35 | G8: 1 | H8: 11.7 | I8: =H8*F8/100 -> 9.28395 | J8: =G8*F8 -> 79.35 | K8: =J8-I8 -> 70.06605 | L8: 29.56 | M8: =K8+L8 -> 99.62605 | N8: Middle East & Africa | O8: 21 | P8: 5 | Q8: FALSE | R8: 8 | S8: Referral | T8: Credit Card | V8: =SUM(G:G) -> 23896
A9: TXN-011743 | B9: 44562 | C9: SELL-3268 | D9: Home Decor | E9: Candles | F9: 75.03 | G9: 1 | H9: 0 | I9: =H9*F9/100 -> 0 | J9: =G9*F9 -> 75.03 | K9: =J9-I9 -> 75.03 | L9: 21.3 | M9: =K9+L9 -> 96.33 | N9: Europe | O9: 10 | P9: 4.5 | Q9: FALSE | R9: 8 | S9: Organic Search | T9: Credit Card
A10: TXN-013295 | B10: 44562 | C10: SELL-7597 | D10: Paper Goods | E10: Prints | F10: 12.71 | G10: 1 | H10: 21.9 | I10: =H10*F10/100 -> 2.78349 | J10: =G10*F10 -> 12.71 | K10: =J10-I10 -> 9.92651 | L10: 8.49 | M10: =K10+L10 -> 18.41651 | N10: North America | O10: 3 | P10: 5 | Q10: FALSE | R10: 10 | S10: Direct | T10: Credit Card | V10: Average Order
A11: TXN-011215 | B11: 44562 | C11: SELL-1078 | D11: Home Decor | E11: Candles | F11: 83.25 | G11: 1 | H11: 0 | I11: =H11*F11/100 -> 0 | J11: =G11*F11 -> 83.25 | K11: =J11-I11 -> 83.25 | L11: 13.74 | M11: =K11+L11 -> 96.99 | N11: Europe | O11: 7 | P11: 4.5 | Q11: FALSE | R11: 12 | S11: Organic Search | T11: PayPal | V11: =AVERAGE(G:G) -> 1.5930667
A12: TXN-012830 | B12: 44563 | C12: SELL-2436 | D12: Home Decor | E12: Vases | F12: 30.75 | G12: 1 | H12: 0 | I12: =H12*F12/100 -> 0 | J12: =G12*F12 -> 30.75 | K12: =J12-I12 -> 30.75 | L12: 10.55 | M12: =K12+L12 -> 41.3 | N12: North America | O12: 6 | P12: 4 | Q12: FALSE | R12: 2 | S12: Social Media | T12: Credit Card
A13: TXN-006582 | B13: 44563 | C13: SELL-7363 | D13: Apparel | E13: Hats | F13: 48.92 | G13: 2 | H13: 0 | I13: =H13*F13/100 -> 0 | J13: =G13*F13 -> 97.84 | K13: =J13-I13 -> 97.84 | L13: 25.81 | M13: =K13+L13 -> 123.65 | N13: Asia-Pacific | O13: 14 | P13: 4.5 | Q13: FALSE | R13: 2 | S13: Organic Search | T13: Google Pay | V13: Average Rating
A14: TXN-005890 | B14: 44563 | C14: SELL-1574 | D14: Textiles | E14: Rugs | F14: 127.59 | G14: 1 | H14: 0 | I14: =H14*F14/100 -> 0 | J14: =G14*F14 -> 127.59 | K14: =J14-I14 -> 127.59 | L14: 20.99 | M14: =K14+L14 -> 148.58 | N14: Europe | O14: 12 | P14: 4.5 | Q14: FALSE | R14: 2 | S14: Paid Ads | T14: Credit Card | V14: =AVERAGE(P:P) -> 4.3518333
A15: TXN-000363 | B15: 44563 | C15: SELL-9932 | D15: Home Decor | E15: Mirrors | F15: 144.23 | G15: 1 | H15: 0 | I15: =H15*F15/100 -> 0 | J15: =G15*F15 -> 144.23 | K15: =J15-I15 -> 144.23 | L15: 11.4 | M15: =K15+L15 -> 155.63 | N15: North America | O15: 2 | P15: 4.5 | Q15: TRUE | R15: 6 | S15: Email | T15: Bank Transfer
A16: TXN-014064 | B16: 44563 | C16: SELL-8899 | D16: Home Decor | E16: Candles | F16: 206.74 | G16: 1 | H16: 0 | I16: =H16*F16/100 -> 0 | J16: =G16*F16 -> 206.74 | K16: =J16-I16 -> 206.74 | L16: 9.79 | M16: =K16+L16 -> 216.53 | N16: North America | O16: 4 | P16: 4 | Q16: TRUE | R16: 2 | S16: Direct | T16: PayPal | V16: Average Delivery Days
A17: TXN-005363 | B17: 44563 | C17: SELL-5522 | D17: Apparel | E17: Jackets | F17: 77.53 | G17: 1 | H17: 0 | I17: =H17*F17/100 -> 0 | J17: =G17*F17 -> 77.53 | K17: =J17-I17 -> 77.53 | L17: 14.5 | M17: =K17+L17 -> 92.03 | N17: North America | O17: 5 | P17: 5 | Q17: FALSE | R17: 10 | S17: Social Media | T17: Bank Transfer | V17: =AVERAGE(O:O) -> 8.5179333
A18: TXN-001896 | B18: 44563 | C18: SELL-5737 | D18: Apparel | E18: Hats | F18: 25.21 | G18: 1 | H18: 0 | I18: =H18*F18/100 -> 0 | J18: =G18*F18 -> 25.21 | K18: =J18-I18 -> 25.21 | L18: 13.69 | M18: =K18+L18 -> 38.9 | N18: Europe | O18: 7 | P18: 5 | Q18: FALSE | R18: 10 | S18: Organic Search | T18: Google Pay
A19: TXN-005071 | B19: 44563 | C19: SELL-1687 | D19: Apparel | E19: T-shirts | F19: 58.06 | G19: 1 | H19: 18 | I19: =H19*F19/100 -> 10.4508 | J19: =G19*F19 -> 58.06 | K19: =J19-I19 -> 47.6092 | L19: 29.52 | M19: =K19+L19 -> 77.1292 | N19: Middle East & Africa | O19: 14 | P19: 1 | Q19: TRUE | R19: 2 | S19: Social Media | T19: Credit Card
A20: TXN-008841 | B20: 44563 | C20: SELL-1958 | D20: Home Decor | E20: Candles | F20: 169.39 | G20: 1 | H20: 0 | I20: =H20*F20/100 -> 0 | J20: =G20*F20 -> 169.39 | K20: =J20-I20 -> 169.39 | L20: 28.51 | M20: =K20+L20 -> 197.9 | N20: Asia-Pacific | O20: 11 | P20: 1 | Q20: FALSE | R20: 12 | S20: Social Media | T20: Google Pay
A21: TXN-012874 | B21: 44563 | C21: SELL-7566 | D21: Jewelry | E21: Bracelets | F21: 172.44 | G21: 1 | H21: 10.5 | I21: =H21*F21/100 -> 18.1062 | J21: =G21*F21 -> 172.44 | K21: =J21-I21 -> 154.3338 | L21: 11.65 | M21: =K21+L21 -> 165.9838 | N21: North America | O21: 5 | P21: 3.5 | Q21: FALSE | R21: 2 | S21: Social Media | T21: Credit Card
A22: TXN-004685 | B22: 44563 | C22: SELL-1643 | D22: Home Decor | E22: Candles | F22: 206.72 | G22: 1 | H22: 0 | I22: =H22*F22/100 -> 0 | J22: =G22*F22 -> 206.72 | K22: =J22-I22 -> 206.72 | L22: 12.2 | M22: =K22+L22 -> 218.92 | N22: North America | O22: 2 | P22: 5 | Q22: TRUE | R22: 12 | S22: Direct | T22: Credit Card
A23: TXN-014167 | B23: 44564 | C23: SELL-1050 | D23: Ceramics | E23: Plates | F23: 35.27 | G23: 1 | H23: 0 | I23: =H23*F23/100 -> 0 | J23: =G23*F23 -> 35.27 | K23: =J23-I23 -> 35.27 | L23: 23.01 | M23: =K23+L23 -> 58.28 | N23: Asia-Pacific | O23: 14 | P23: 5 | Q23: FALSE | R23: 1 | S23: Paid Ads | T23: Google Pay
A24: TXN-004704 | B24: 44564 | C24: SELL-4622 | D24: Paper Goods | E24: Journals | F24: 19.32 | G24: 1 | H24: 21.8 | I24: =H24*F24/100 -> 4.21176 | J24: =G24*F24 -> 19.32 | K24: =J24-I24 -> 15.10824 | L24: 10.29 | M24: =K24+L24 -> 25.39824 | N24: North America | O24: 5 | P24: 4 | Q24: FALSE | R24: 2 | S24: Referral | T24: PayPal
A25: TXN-007380 | B25: 44564 | C25: SELL-4238 | D25: Jewelry | E25: Earrings | F25: 54.96 | G25: 5 | H25: 0 | I25: =H25*F25/100 -> 0 | J25: =G25*F25 -> 274.8 | K25: =J25-I25 -> 274.8 | L25: 20.81 | M25: =K25+L25 -> 295.61 | N25: Asia-Pacific | O25: 16 | P25: 1 | Q25: TRUE | R25: 8 | S25: Email | T25: Credit Card
A26: TXN-011264 | B26: 44564 | C26: SELL-5348 | D26: Jewelry | E26: Rings | F26: 162.21 | G26: 1 | H26: 0 | I26: =H26*F26/100 -> 0 | J26: =G26*F26 -> 162.21 | K26: =J26-I26 -> 162.21 | L26: 20.03 | M26: =K26+L26 -> 182.24 | N26: Europe | O26: 8 | P26: 5 | Q26: FALSE | R26: 2 | S26: Organic Search | T26: Apple Pay
A27: TXN-010121 | B27: 44564 | C27: SELL-9978 | D27: Apparel | E27: Scarves | F27: 116.93 | G27: 1 | H27: 0 | I27: =H27*F27/100 -> 0 | J27: =G27*F27 -> 116.93 | K27: =J27-I27 -> 116.93 | L27: 14.75 | M27: =K27+L27 -> 131.68 | N27: North America | O27: 2 | P27: 5 | Q27: FALSE | R27: 12 | S27: Email | T27: Credit Card
A28: TXN-002874 | B28: 44564 | C28: SELL-9859 | D28: Home Decor | E28: Wall Art | F28: 113.2 | G28: 1 | H28: 0 | I28: =H28*F28/100 -> 0 | J28: =G28*F28 -> 113.2 | K28: =J28-I28 -> 113.2 | L28: 9.53 | M28: =K28+L28 -> 122.73 | N28: North America | O28: 3 | P28: 5 | Q28: FALSE | R28: 1 | S28: Direct | T28: PayPal
A29: TXN-004859 | B29: 44564 | C29: SELL-7219 | D29: Woodwork | E29: Furniture | F29: 163.64 | G29: 2 | H29: 7.7 | I29: =H29*F29/100 -> 12.60028 | J29: =G29*F29 -> 327.28 | K29: =J29-I29 -> 314.67972 | L29: 10.72 | M29: =K29+L29 -> 325.39972 | N29: North America | O29: 3 | P29: 5 | Q29: FALSE | R29: 4 | S29: Paid Ads | T29: Google Pay
... A15001: TXN-006313 | B15001: 45929 | C15001: SELL-8503 | D15001: Apparel | E15001: Scarves | F15001: 115.32 | G15001: 2 | H15001: 0 | I15001: =H15001*F15001/100 -> 0 | J15001: =G15001*F15001 -> 230.64 | K15001: =J15001-I15001 -> 230.64 | L15001: 21.14 | M15001: =K15001+L15001 -> 251.78 | N15001: Europe | O15001: 6 | P15001: 5 | Q15001: FALSE | R15001: 1 | S15001: Paid Ads | T15001: PayPal

Sheet DASHBOARD
A6: =GETPIVOTDATA("Total order",'PIVOT TABLE'!$A$3) -> 2549666.3 | D6: =GETPIVOTDATA("Average of Total order",'PIVOT TABLE'!$A$31) -> 169.97776 | G6: =GETPIVOTDATA("Quantity",'PIVOT TABLE'!$A$31) -> 23896 | K6: =GETPIVOTDATA("Sum of Discout Amount",'PIVOT TABLE'!$A$15) -> 50102.421 | N6: =GETPIVOTDATA("Average of Customer Rating",'PIVOT TABLE'!$A$31) -> 4.3518333 | Q6: ='CLEANED DATA'!V17 -> 8.5179333 | U6: =GETPIVOTDATA("Percentage",'PIVOT TABLE'!$A$26,"Is Custom Order","TRUE") -> 0.18542687
